Exception on /histogram [GET]
Traceback (most recent call last):
  File "/Users/memoMac/Documents/Projects/venv-mlt-analyser/lib/python2.7/site-packages/flask/app.py", line 1817, in wsgi_app
    response = self.full_dispatch_request()
  File "/Users/memoMac/Documents/Projects/venv-mlt-analyser/lib/python2.7/site-packages/flask/app.py", line 1477, in full_dispatch_request
    rv = self.handle_user_exception(e)
  File "/Users/memoMac/Documents/Projects/venv-mlt-analyser/lib/python2.7/site-packages/flask/app.py", line 1381, in handle_user_exception
    reraise(exc_type, exc_value, tb)
  File "/Users/memoMac/Documents/Projects/venv-mlt-analyser/lib/python2.7/site-packages/flask/app.py", line 1475, in full_dispatch_request
    rv = self.dispatch_request()
  File "/Users/memoMac/Documents/Projects/venv-mlt-analyser/lib/python2.7/site-packages/flask/app.py", line 1461, in dispatch_request
    return self.view_functions[rule.endpoint](**req.view_args)
  File "app.py", line 30, in todos
    histogram = dict(1, entries[1])
TypeError: dict expected at most 1 arguments, got 2
Exception on /histogram [GET]
Traceback (most recent call last):
  File "/Users/memoMac/Documents/Projects/venv-mlt-analyser/lib/python2.7/site-packages/flask/app.py", line 1817, in wsgi_app
    response = self.full_dispatch_request()
  File "/Users/memoMac/Documents/Projects/venv-mlt-analyser/lib/python2.7/site-packages/flask/app.py", line 1477, in full_dispatch_request
    rv = self.handle_user_exception(e)
  File "/Users/memoMac/Documents/Projects/venv-mlt-analyser/lib/python2.7/site-packages/flask/app.py", line 1381, in handle_user_exception
    reraise(exc_type, exc_value, tb)
  File "/Users/memoMac/Documents/Projects/venv-mlt-analyser/lib/python2.7/site-packages/flask/app.py", line 1475, in full_dispatch_request
    rv = self.dispatch_request()
  File "/Users/memoMac/Documents/Projects/venv-mlt-analyser/lib/python2.7/site-packages/flask/app.py", line 1461, in dispatch_request
    return self.view_functions[rule.endpoint](**req.view_args)
  File "app.py", line 32, in todos
    for idx, val in enumerate(entries)[1:]:
TypeError: 'enumerate' object has no attribute '__getitem__'
